<?xml version="1.0" encoding="UTF-8"?>
<testng-results skipped="1" failed="4" ignored="0" total="9" passed="4">
  <reporter-output>
  </reporter-output>
  <suite name="Functional Suite" duration-ms="228" started-at="2019-12-12T20:47:11 IST" finished-at="2019-12-12T20:47:11 IST">
    <groups>
      <group name="bvt">
        <method signature="TestCase_TestCaseDependency.fourthTest()[pri:4, instance:testcases.TestCase_TestCaseDependency@2758fe70]" name="fourthTest" class="testcases.TestCase_TestCaseDependency"/>
      </group> <!-- bvt -->
      <group name="functional">
        <method signature="TestCase1.doLogin()[pri:2, instance:testcases.TestCase1@527740a2]" name="doLogin" class="testcases.TestCase1"/>
        <method signature="TestCase1.doUserReg()[pri:1, instance:testcases.TestCase1@527740a2]" name="doUserReg" class="testcases.TestCase1"/>
        <method signature="TestCase_TestCaseDependency.doUserReg()[pri:1, instance:testcases.TestCase_TestCaseDependency@2758fe70]" name="doUserReg" class="testcases.TestCase_TestCaseDependency"/>
        <method signature="TestCase_TestCaseDependency.thirdTest()[pri:3, instance:testcases.TestCase_TestCaseDependency@2758fe70]" name="thirdTest" class="testcases.TestCase_TestCaseDependency"/>
        <method signature="TestCase_TestCaseDependency.doLogin()[pri:3, instance:testcases.TestCase_TestCaseDependency@2758fe70]" name="doLogin" class="testcases.TestCase_TestCaseDependency"/>
        <method signature="TestCase_SoftAssertion.validateTitle()[pri:0, instance:testcases.TestCase_SoftAssertion@3b084709]" name="validateTitle" class="testcases.TestCase_SoftAssertion"/>
      </group> <!-- functional -->
      <group name="smoke">
        <method signature="TestCase2.validateTitle()[pri:0, instance:testcases.TestCase2@47ef968d]" name="validateTitle" class="testcases.TestCase2"/>
        <method signature="TestCase_TestCaseDependency.doUserReg()[pri:1, instance:testcases.TestCase_TestCaseDependency@2758fe70]" name="doUserReg" class="testcases.TestCase_TestCaseDependency"/>
        <method signature="TestCase_TestCaseDependency.thirdTest()[pri:3, instance:testcases.TestCase_TestCaseDependency@2758fe70]" name="thirdTest" class="testcases.TestCase_TestCaseDependency"/>
        <method signature="TestCase_TestCaseDependency.doLogin()[pri:3, instance:testcases.TestCase_TestCaseDependency@2758fe70]" name="doLogin" class="testcases.TestCase_TestCaseDependency"/>
        <method signature="TestCase_SoftAssertion.validateTitle()[pri:0, instance:testcases.TestCase_SoftAssertion@3b084709]" name="validateTitle" class="testcases.TestCase_SoftAssertion"/>
      </group> <!-- smoke -->
    </groups>
    <test name="Login Test" duration-ms="36" started-at="2019-12-12T20:47:11 IST" finished-at="2019-12-12T20:47:11 IST">
      <class name="testcases.TestCase1">
        <test-method status="PASS" signature="creatingDBConn()[pri:0, instance:testcases.TestCase1@527740a2]" name="creatingDBConn" is-config="true" duration-ms="0" started-at="2019-12-12T20:47:11 IST" finished-at="2019-12-12T20:47:11 IST">
          <reporter-output>
          </reporter-output>
        </test-method> <!-- creatingDBConn -->
        <test-method status="PASS" signature="launchBrowser()[pri:0, instance:testcases.TestCase1@527740a2]" name="launchBrowser" is-config="true" duration-ms="0" started-at="2019-12-12T20:47:11 IST" finished-at="2019-12-12T20:47:11 IST">
          <reporter-output>
          </reporter-output>
        </test-method> <!-- launchBrowser -->
        <test-method status="PASS" signature="doUserReg()[pri:1, instance:testcases.TestCase1@527740a2]" name="doUserReg" duration-ms="6" started-at="2019-12-12T20:47:11 IST" finished-at="2019-12-12T20:47:11 IST">
          <reporter-output>
          </reporter-output>
        </test-method> <!-- doUserReg -->
        <test-method status="PASS" signature="closeBrowser()[pri:0, instance:testcases.TestCase1@527740a2]" name="closeBrowser" is-config="true" duration-ms="0" started-at="2019-12-12T20:47:11 IST" finished-at="2019-12-12T20:47:11 IST">
          <reporter-output>
          </reporter-output>
        </test-method> <!-- closeBrowser -->
        <test-method status="PASS" signature="doLogin()[pri:2, instance:testcases.TestCase1@527740a2]" name="doLogin" duration-ms="2" started-at="2019-12-12T20:47:11 IST" finished-at="2019-12-12T20:47:11 IST">
          <reporter-output>
          </reporter-output>
        </test-method> <!-- doLogin -->
        <test-method status="PASS" signature="launchBrowser()[pri:0, instance:testcases.TestCase1@527740a2]" name="launchBrowser" is-config="true" duration-ms="0" started-at="2019-12-12T20:47:11 IST" finished-at="2019-12-12T20:47:11 IST">
          <reporter-output>
          </reporter-output>
        </test-method> <!-- launchBrowser -->
        <test-method status="PASS" signature="closeBrowser()[pri:0, instance:testcases.TestCase1@527740a2]" name="closeBrowser" is-config="true" duration-ms="0" started-at="2019-12-12T20:47:11 IST" finished-at="2019-12-12T20:47:11 IST">
          <reporter-output>
          </reporter-output>
        </test-method> <!-- closeBrowser -->
        <test-method status="PASS" signature="closingDBConn()[pri:0, instance:testcases.TestCase1@527740a2]" name="closingDBConn" is-config="true" duration-ms="0" started-at="2019-12-12T20:47:11 IST" finished-at="2019-12-12T20:47:11 IST">
          <reporter-output>
          </reporter-output>
        </test-method> <!-- closingDBConn -->
      </class> <!-- testcases.TestCase1 -->
    </test> <!-- Login Test -->
    <test name="Validate Titile Name" duration-ms="10" started-at="2019-12-12T20:47:11 IST" finished-at="2019-12-12T20:47:11 IST">
      <class name="testcases.TestCase2">
        <test-method status="FAIL" signature="validateTitle()[pri:0, instance:testcases.TestCase2@47ef968d]" name="validateTitle" duration-ms="3" started-at="2019-12-12T20:47:11 IST" finished-at="2019-12-12T20:47:11 IST">
          <exception class="java.lang.AssertionError">
            <message>
              <![CDATA[expected [Google] but found [Yahoo]]]>
            </message>
            <full-stacktrace>
              <![CDATA[java.lang.AssertionError: expected [Google] but found [Yahoo]
at org.testng.Assert.fail(Assert.java:97)
at org.testng.Assert.assertEqualsImpl(Assert.java:136)
at org.testng.Assert.assertEquals(Assert.java:118)
at org.testng.Assert.assertEquals(Assert.java:575)
at org.testng.Assert.assertEquals(Assert.java:585)
at testcases.TestCase2.validateTitle(TestCase2.java:13)
at sun.reflect.NativeMethodAccessorImpl.invoke0(Native Method)
at sun.reflect.NativeMethodAccessorImpl.invoke(NativeMethodAccessorImpl.java:62)
at sun.reflect.DelegatingMethodAccessorImpl.invoke(DelegatingMethodAccessorImpl.java:43)
at java.lang.reflect.Method.invoke(Method.java:498)
at org.testng.internal.MethodInvocationHelper.invokeMethod(MethodInvocationHelper.java:133)
at org.testng.internal.TestInvoker.invokeMethod(TestInvoker.java:584)
at org.testng.internal.TestInvoker.invokeTestMethod(TestInvoker.java:172)
at org.testng.internal.MethodRunner.runInSequence(MethodRunner.java:46)
at org.testng.internal.TestInvoker$MethodInvocationAgent.invoke(TestInvoker.java:804)
at org.testng.internal.TestInvoker.invokeTestMethods(TestInvoker.java:145)
at org.testng.internal.TestMethodWorker.invokeTestMethods(TestMethodWorker.java:146)
at org.testng.internal.TestMethodWorker.run(TestMethodWorker.java:128)
at java.util.ArrayList.forEach(ArrayList.java:1257)
at org.testng.TestRunner.privateRun(TestRunner.java:770)
at org.testng.TestRunner.run(TestRunner.java:591)
at org.testng.SuiteRunner.runTest(SuiteRunner.java:402)
at org.testng.SuiteRunner.runSequentially(SuiteRunner.java:396)
at org.testng.SuiteRunner.privateRun(SuiteRunner.java:355)
at org.testng.SuiteRunner.run(SuiteRunner.java:304)
at org.testng.SuiteRunnerWorker.runSuite(SuiteRunnerWorker.java:53)
at org.testng.SuiteRunnerWorker.run(SuiteRunnerWorker.java:96)
at org.testng.TestNG.runSuitesSequentially(TestNG.java:1180)
at org.testng.TestNG.runSuitesLocally(TestNG.java:1102)
at org.testng.TestNG.runSuites(TestNG.java:1032)
at org.testng.TestNG.run(TestNG.java:1000)
at org.testng.remote.AbstractRemoteTestNG.run(AbstractRemoteTestNG.java:115)
at org.testng.remote.RemoteTestNG.initAndRun(RemoteTestNG.java:251)
at org.testng.remote.RemoteTestNG.main(RemoteTestNG.java:77)
]]>
            </full-stacktrace>
          </exception> <!-- java.lang.AssertionError -->
          <reporter-output>
          </reporter-output>
        </test-method> <!-- validateTitle -->
      </class> <!-- testcases.TestCase2 -->
    </test> <!-- Validate Titile Name -->
    <test name="Test Dependency" duration-ms="15" started-at="2019-12-12T20:47:11 IST" finished-at="2019-12-12T20:47:11 IST">
      <class name="testcases.TestCase_TestCaseDependency">
        <test-method status="FAIL" signature="doUserReg()[pri:1, instance:testcases.TestCase_TestCaseDependency@2758fe70]" name="doUserReg" duration-ms="1" started-at="2019-12-12T20:47:11 IST" finished-at="2019-12-12T20:47:11 IST">
          <exception class="java.lang.AssertionError">
            <message>
              <![CDATA[User is not registered successfully]]>
            </message>
            <full-stacktrace>
              <![CDATA[java.lang.AssertionError: User is not registered successfully
at org.testng.Assert.fail(Assert.java:97)
at testcases.TestCase_TestCaseDependency.doUserReg(TestCase_TestCaseDependency.java:12)
at sun.reflect.NativeMethodAccessorImpl.invoke0(Native Method)
at sun.reflect.NativeMethodAccessorImpl.invoke(NativeMethodAccessorImpl.java:62)
at sun.reflect.DelegatingMethodAccessorImpl.invoke(DelegatingMethodAccessorImpl.java:43)
at java.lang.reflect.Method.invoke(Method.java:498)
at org.testng.internal.MethodInvocationHelper.invokeMethod(MethodInvocationHelper.java:133)
at org.testng.internal.TestInvoker.invokeMethod(TestInvoker.java:584)
at org.testng.internal.TestInvoker.invokeTestMethod(TestInvoker.java:172)
at org.testng.internal.MethodRunner.runInSequence(MethodRunner.java:46)
at org.testng.internal.TestInvoker$MethodInvocationAgent.invoke(TestInvoker.java:804)
at org.testng.internal.TestInvoker.invokeTestMethods(TestInvoker.java:145)
at org.testng.internal.TestMethodWorker.invokeTestMethods(TestMethodWorker.java:146)
at org.testng.internal.TestMethodWorker.run(TestMethodWorker.java:128)
at java.util.ArrayList.forEach(ArrayList.java:1257)
at org.testng.TestRunner.privateRun(TestRunner.java:770)
at org.testng.TestRunner.run(TestRunner.java:591)
at org.testng.SuiteRunner.runTest(SuiteRunner.java:402)
at org.testng.SuiteRunner.runSequentially(SuiteRunner.java:396)
at org.testng.SuiteRunner.privateRun(SuiteRunner.java:355)
at org.testng.SuiteRunner.run(SuiteRunner.java:304)
at org.testng.SuiteRunnerWorker.runSuite(SuiteRunnerWorker.java:53)
at org.testng.SuiteRunnerWorker.run(SuiteRunnerWorker.java:96)
at org.testng.TestNG.runSuitesSequentially(TestNG.java:1180)
at org.testng.TestNG.runSuitesLocally(TestNG.java:1102)
at org.testng.TestNG.runSuites(TestNG.java:1032)
at org.testng.TestNG.run(TestNG.java:1000)
at org.testng.remote.AbstractRemoteTestNG.run(AbstractRemoteTestNG.java:115)
at org.testng.remote.RemoteTestNG.initAndRun(RemoteTestNG.java:251)
at org.testng.remote.RemoteTestNG.main(RemoteTestNG.java:77)
]]>
            </full-stacktrace>
          </exception> <!-- java.lang.AssertionError -->
          <reporter-output>
          </reporter-output>
        </test-method> <!-- doUserReg -->
        <test-method status="PASS" signature="thirdTest()[pri:3, instance:testcases.TestCase_TestCaseDependency@2758fe70]" name="thirdTest" duration-ms="1" started-at="2019-12-12T20:47:11 IST" depends-on-methods="testcases.TestCase_TestCaseDependency.doUserReg" finished-at="2019-12-12T20:47:11 IST">
          <reporter-output>
          </reporter-output>
        </test-method> <!-- thirdTest -->
        <test-method status="SKIP" signature="doLogin()[pri:3, instance:testcases.TestCase_TestCaseDependency@2758fe70]" name="doLogin" duration-ms="0" started-at="2019-12-12T20:47:11 IST" depends-on-methods="testcases.TestCase_TestCaseDependency.thirdTest, testcases.TestCase_TestCaseDependency.doUserReg" finished-at="2019-12-12T20:47:11 IST">
          <exception class="java.lang.Throwable">
            <message>
              <![CDATA[Method TestCase_TestCaseDependency.doLogin()[pri:3, instance:testcases.TestCase_TestCaseDependency@2758fe70] depends on not successfully finished methods]]>
            </message>
            <full-stacktrace>
              <![CDATA[java.lang.Throwable: Method TestCase_TestCaseDependency.doLogin()[pri:3, instance:testcases.TestCase_TestCaseDependency@2758fe70] depends on not successfully finished methods
at org.testng.internal.TestInvoker.invokeTestMethods(TestInvoker.java:99)
at org.testng.internal.TestMethodWorker.invokeTestMethods(TestMethodWorker.java:146)
at org.testng.internal.TestMethodWorker.run(TestMethodWorker.java:128)
at java.util.ArrayList.forEach(ArrayList.java:1257)
at org.testng.TestRunner.privateRun(TestRunner.java:770)
at org.testng.TestRunner.run(TestRunner.java:591)
at org.testng.SuiteRunner.runTest(SuiteRunner.java:402)
at org.testng.SuiteRunner.runSequentially(SuiteRunner.java:396)
at org.testng.SuiteRunner.privateRun(SuiteRunner.java:355)
at org.testng.SuiteRunner.run(SuiteRunner.java:304)
at org.testng.SuiteRunnerWorker.runSuite(SuiteRunnerWorker.java:53)
at org.testng.SuiteRunnerWorker.run(SuiteRunnerWorker.java:96)
at org.testng.TestNG.runSuitesSequentially(TestNG.java:1180)
at org.testng.TestNG.runSuitesLocally(TestNG.java:1102)
at org.testng.TestNG.runSuites(TestNG.java:1032)
at org.testng.TestNG.run(TestNG.java:1000)
at org.testng.remote.AbstractRemoteTestNG.run(AbstractRemoteTestNG.java:115)
at org.testng.remote.RemoteTestNG.initAndRun(RemoteTestNG.java:251)
at org.testng.remote.RemoteTestNG.main(RemoteTestNG.java:77)
]]>
            </full-stacktrace>
          </exception> <!-- java.lang.Throwable -->
          <reporter-output>
          </reporter-output>
        </test-method> <!-- doLogin -->
        <test-method status="PASS" signature="fourthTest()[pri:4, instance:testcases.TestCase_TestCaseDependency@2758fe70]" name="fourthTest" duration-ms="2" started-at="2019-12-12T20:47:11 IST" finished-at="2019-12-12T20:47:11 IST">
          <reporter-output>
          </reporter-output>
        </test-method> <!-- fourthTest -->
      </class> <!-- testcases.TestCase_TestCaseDependency -->
    </test> <!-- Test Dependency -->
    <test name="Test Failure" duration-ms="3" started-at="2019-12-12T20:47:11 IST" finished-at="2019-12-12T20:47:11 IST">
      <class name="testcases.TestFailures">
        <test-method status="FAIL" signature="doLogin()[pri:0, instance:testcases.TestFailures@49fc609f]" name="doLogin" duration-ms="0" started-at="2019-12-12T20:47:11 IST" finished-at="2019-12-12T20:47:11 IST">
          <exception class="java.lang.AssertionError">
            <message>
              <![CDATA[Failing test case]]>
            </message>
            <full-stacktrace>
              <![CDATA[java.lang.AssertionError: Failing test case
at org.testng.Assert.fail(Assert.java:97)
at testcases.TestFailures.doLogin(TestFailures.java:10)
at sun.reflect.NativeMethodAccessorImpl.invoke0(Native Method)
at sun.reflect.NativeMethodAccessorImpl.invoke(NativeMethodAccessorImpl.java:62)
at sun.reflect.DelegatingMethodAccessorImpl.invoke(DelegatingMethodAccessorImpl.java:43)
at java.lang.reflect.Method.invoke(Method.java:498)
at org.testng.internal.MethodInvocationHelper.invokeMethod(MethodInvocationHelper.java:133)
at org.testng.internal.TestInvoker.invokeMethod(TestInvoker.java:584)
at org.testng.internal.TestInvoker.invokeTestMethod(TestInvoker.java:172)
at org.testng.internal.MethodRunner.runInSequence(MethodRunner.java:46)
at org.testng.internal.TestInvoker$MethodInvocationAgent.invoke(TestInvoker.java:804)
at org.testng.internal.TestInvoker.invokeTestMethods(TestInvoker.java:145)
at org.testng.internal.TestMethodWorker.invokeTestMethods(TestMethodWorker.java:146)
at org.testng.internal.TestMethodWorker.run(TestMethodWorker.java:128)
at java.util.ArrayList.forEach(ArrayList.java:1257)
at org.testng.TestRunner.privateRun(TestRunner.java:770)
at org.testng.TestRunner.run(TestRunner.java:591)
at org.testng.SuiteRunner.runTest(SuiteRunner.java:402)
at org.testng.SuiteRunner.runSequentially(SuiteRunner.java:396)
at org.testng.SuiteRunner.privateRun(SuiteRunner.java:355)
at org.testng.SuiteRunner.run(SuiteRunner.java:304)
at org.testng.SuiteRunnerWorker.runSuite(SuiteRunnerWorker.java:53)
at org.testng.SuiteRunnerWorker.run(SuiteRunnerWorker.java:96)
at org.testng.TestNG.runSuitesSequentially(TestNG.java:1180)
at org.testng.TestNG.runSuitesLocally(TestNG.java:1102)
at org.testng.TestNG.runSuites(TestNG.java:1032)
at org.testng.TestNG.run(TestNG.java:1000)
at org.testng.remote.AbstractRemoteTestNG.run(AbstractRemoteTestNG.java:115)
at org.testng.remote.RemoteTestNG.initAndRun(RemoteTestNG.java:251)
at org.testng.remote.RemoteTestNG.main(RemoteTestNG.java:77)
]]>
            </full-stacktrace>
          </exception> <!-- java.lang.AssertionError -->
          <reporter-output>
          </reporter-output>
        </test-method> <!-- doLogin -->
      </class> <!-- testcases.TestFailures -->
    </test> <!-- Test Failure -->
    <test name="Assertions" duration-ms="5" started-at="2019-12-12T20:47:11 IST" finished-at="2019-12-12T20:47:11 IST">
      <class name="testcases.TestCase_SoftAssertion">
        <test-method status="PASS" signature="setUp()[pri:0, instance:testcases.TestCase_SoftAssertion@3b084709]" name="setUp" is-config="true" duration-ms="9" started-at="2019-12-12T20:47:11 IST" finished-at="2019-12-12T20:47:11 IST">
          <reporter-output>
          </reporter-output>
        </test-method> <!-- setUp -->
        <test-method status="FAIL" signature="validateTitle()[pri:0, instance:testcases.TestCase_SoftAssertion@3b084709]" name="validateTitle" duration-ms="4" started-at="2019-12-12T20:47:11 IST" finished-at="2019-12-12T20:47:11 IST">
          <exception class="java.lang.AssertionError">
            <message>
              <![CDATA[The following asserts failed:
Title is not matching:  expected [Google] but found [Yahoo],
Codition is not matching:  expected [false] but found [true],
Test1 is getting failed:  expected [false] but found [true]]]>
            </message>
            <full-stacktrace>
              <![CDATA[java.lang.AssertionError: The following asserts failed:
Title is not matching:  expected [Google] but found [Yahoo],
Codition is not matching:  expected [false] but found [true],
Test1 is getting failed:  expected [false] but found [true]
at org.testng.asserts.SoftAssert.assertAll(SoftAssert.java:47)
at org.testng.asserts.SoftAssert.assertAll(SoftAssert.java:31)
at testcases.TestCase_SoftAssertion.validateTitle(TestCase_SoftAssertion.java:49)
at sun.reflect.NativeMethodAccessorImpl.invoke0(Native Method)
at sun.reflect.NativeMethodAccessorImpl.invoke(NativeMethodAccessorImpl.java:62)
at sun.reflect.DelegatingMethodAccessorImpl.invoke(DelegatingMethodAccessorImpl.java:43)
at java.lang.reflect.Method.invoke(Method.java:498)
at org.testng.internal.MethodInvocationHelper.invokeMethod(MethodInvocationHelper.java:133)
at org.testng.internal.TestInvoker.invokeMethod(TestInvoker.java:584)
at org.testng.internal.TestInvoker.invokeTestMethod(TestInvoker.java:172)
at org.testng.internal.MethodRunner.runInSequence(MethodRunner.java:46)
at org.testng.internal.TestInvoker$MethodInvocationAgent.invoke(TestInvoker.java:804)
at org.testng.internal.TestInvoker.invokeTestMethods(TestInvoker.java:145)
at org.testng.internal.TestMethodWorker.invokeTestMethods(TestMethodWorker.java:146)
at org.testng.internal.TestMethodWorker.run(TestMethodWorker.java:128)
at java.util.ArrayList.forEach(ArrayList.java:1257)
at org.testng.TestRunner.privateRun(TestRunner.java:770)
at org.testng.TestRunner.run(TestRunner.java:591)
at org.testng.SuiteRunner.runTest(SuiteRunner.java:402)
at org.testng.SuiteRunner.runSequentially(SuiteRunner.java:396)
at org.testng.SuiteRunner.privateRun(SuiteRunner.java:355)
at org.testng.SuiteRunner.run(SuiteRunner.java:304)
at org.testng.SuiteRunnerWorker.runSuite(SuiteRunnerWorker.java:53)
at org.testng.SuiteRunnerWorker.run(SuiteRunnerWorker.java:96)
at org.testng.TestNG.runSuitesSequentially(TestNG.java:1180)
at org.testng.TestNG.runSuitesLocally(TestNG.java:1102)
at org.testng.TestNG.runSuites(TestNG.java:1032)
at org.testng.TestNG.run(TestNG.java:1000)
at org.testng.remote.AbstractRemoteTestNG.run(AbstractRemoteTestNG.java:115)
at org.testng.remote.RemoteTestNG.initAndRun(RemoteTestNG.java:251)
at org.testng.remote.RemoteTestNG.main(RemoteTestNG.java:77)
]]>
            </full-stacktrace>
          </exception> <!-- java.lang.AssertionError -->
          <reporter-output>
          </reporter-output>
        </test-method> <!-- validateTitle -->
        <test-method status="PASS" signature="tearDown()[pri:0, instance:testcases.TestCase_SoftAssertion@3b084709]" name="tearDown" is-config="true" duration-ms="0" started-at="2019-12-12T20:47:11 IST" finished-at="2019-12-12T20:47:11 IST">
          <reporter-output>
          </reporter-output>
        </test-method> <!-- tearDown -->
      </class> <!-- testcases.TestCase_SoftAssertion -->
    </test> <!-- Assertions -->
  </suite> <!-- Functional Suite -->
</testng-results>
